Workbook

Sheet T=36
A1: T | B1: Arrival | C1: Ins. ID | D1: OUR APPROACH | M1: MILP | N1: MIPGap | O1: t | P1: ECR | R1: while_available | T1: waiting buffer | AB1: full_capacity | AK1: MAX | AL1: MIN
D2: val. | E2: mcts_time | G2: sim_time | H2: RDI | I2: AVG | J2: AVG RDI | K2: MAX | L2: MIN | T2: 3 | V2: 6 | X2: 9 | Z2: 12 | AB2: 0.2 | AD2: 0.4 | AF2: 0.6 | AH2: 0.8
A3: 36 | B3: Uniform | C3: #1 | D3: 1198.1935 | E3: 7.1823608 | F3: =AVERAGE(E3:E7) -> 5.2009111 | G3: 64.820932 | H3: =(D3-AL3)/(AK3-AL3) -> 1 | I3: =AVERAGE(D3:D7) -> 981.23584 | J3: =AVERAGE(H3:H7) -> 0.90654461 | K3: =MAX(D3:D7) -> 1198.1935 | L3: =MIN(D3:D7) -> 836.5974 | M3: 1198.19 | N3: 0 | O3: 0.61 | P3: =M3/I3 -> 1.221103 | R3: -137.82096 | S3: =(R3-AL3)/(AK3-AL3) -> 0.42450634 | T3: -137.82096 | U3: =(T3-AL3)/(AK3-AL3) -> 0.42450634 | V3: -137.82096 | W3: =(V3-AL3)/(AK3-AL3) -> 0.42450634 | X3: 302.88833 | Y3: =(X3-AL3)/(AK3-AL3) -> 0.61434366 | Z3: -15.618576 | AA3: =(Z3-AL3)/(AK3-AL3) -> 0.47714551 | AB3: 664.48443 | AC3: =(AB3-AL3)/(AK3-AL3) -> 0.77010265 | AD3: -87.894675 | AE3: =(AD3-AL3)/(AK3-AL3) -> 0.44601229 | AF3: 445.8144 | AG3: =(AF3-AL3)/(AK3-AL3) -> 0.67590964 | AH3: -1123.3168 | AI3: =(AH3-AL3)/(AK3-AL3) -> 0 | AK3: =MAX(D3:D7,R3,T3,V3,X3,Z3,AB3,AD3,AF3,AH3) -> 1198.1935 | AL3: =MIN(D3:D7,R3,T3,V3,X3,Z3,AB3,AD3,AF3,AH3) -> -1123.3168
D4: 836.5974 | E4: 3.6455215 | G4: 43.783098 | H4: =(D4-AL4)/(AK4-AL4) -> 0.84424101 | AK4: 1198.1935 | AL4: -1123.3168
D5: 836.5974 | E5: 4.5684783 | G5: 59.428051 | H5: =(D5-AL5)/(AK5-AL5) -> 0.84424101 | AK5: 1198.1935 | AL5: -1123.3168
D6: 836.5974 | E6: 3.7518871 | G6: 45.058489 | H6: =(D6-AL6)/(AK6-AL6) -> 0.84424101 | AK6: 1198.1935 | AL6: -1123.3168
D7: 1198.1935 | E7: 6.8563076 | G7: 41.706232 | H7: =(D7-AL7)/(AK7-AL7) -> 1 | AK7: 1198.1935 | AL7: -1123.3168
C8: #2 | D8: 1090.1251 | E8: 6.6216272 | F8: =AVERAGE(E8:E12) -> 6.4690571 | G8: 105.99383 | H8: =(D8-AL8)/(AK8-AL8) -> 0.58866904 | I8: =AVERAGE(D8:D12) -> 1318.9508 | J8: =AVERAGE(H8:H12) -> 0.75320142 | K8: =MAX(D8:D12) -> 1662.1895 | L8: =MIN(D8:D12) -> 1090.1251 | M8: 1662.1 | N8: 3e-06 | O8: 4.66 | P8: =M8/I8 -> 1.2601683 | R8: 365.62601 | S8: =(R8-AL8)/(AK8-AL8) -> 0.06773319 | T8: 736.42113 | U8: =(T8-AL8)/(AK8-AL8) -> 0.33434565 | V8: 1058.1319 | W8: =(V8-AL8)/(AK8-AL8) -> 0.56566505 | X8: 1198.6397 | Y8: =(X8-AL8)/(AK8-AL8) -> 0.66669425 | Z8: 271.4251 | AA8: =(Z8-AL8)/(AK8-AL8) -> 0 | AB8: 1083.8876 | AC8: =(AB8-AL8)/(AK8-AL8) -> 0.58418415 | AD8: 1165.3917 | AE8: =(AD8-AL8)/(AK8-AL8) -> 0.64278793 | AF8: 492.92559 | AG8: =(AF8-AL8)/(AK8-AL8) -> 0.15926528 | AH8: 487.10499 | AI8: =(AH8-AL8)/(AK8-AL8) -> 0.1550801 | AK8: =MAX(D8:D12,R8,T8,V8,X8,Z8,AB8,AD8,AF8,AH8) -> 1662.1895 | AL8: =MIN(D8:D12,R8,T8,V8,X8,Z8,AB8,AD8,AF8,AH8) -> 271.4251
D9: 1662.1895 | E9: 5.5372995 | G9: 138.50218 | H9: =(D9-AL9)/(AK9-AL9) -> 1 | AK9: 1662.1895 | AL9: 271.4251
D10: 1090.1251 | E10: 7.1150824 | G10: 106.77005 | H10: =(D10-AL10)/(AK10-AL10) -> 0.58866904 | AK10: 1662.1895 | AL10: 271.4251
D11: 1662.1895 | E11: 5.9061472 | G11: 153.63749 | H11: =(D11-AL11)/(AK11-AL11) -> 1 | AK11: 1662.1895 | AL11: 271.4251
D12: 1090.1251 | E12: 7.1651293 | G12: 107.52473 | H12: =(D12-AL12)/(AK12-AL12) -> 0.58866904 | AK12: 1662.1895 | AL12: 271.4251
C13: #3 | D13: 2139.3092 | E13: 6.1216243 | F13: =AVERAGE(E13:E17) -> 5.8116668 | G13: 98.003736 | H13: =(D13-AL13)/(AK13-AL13) -> 0.90691514 | I13: =AVERAGE(D13:D17) -> 2164.0885 | J13: =AVERAGE(H13:H17) -> 0.92553211 | K13: =MAX(D13:D17) -> 2263.2058 | L13: =MIN(D13:D17) -> 2139.3092 | M13: 2482.14 | N13: 0 | O13: 96.21 | P13: =M13/I13 -> 1.1469679 | R13: 1251.1861 | S13: =(R13-AL13)/(AK13-AL13) -> 0.2396587 | T13: 1164.9637 | U13: =(T13-AL13)/(AK13-AL13) -> 0.17487888 | V13: 1786.3828 | W13: =(V13-AL13)/(AK13-AL13) -> 0.64175776 | X13: 939.3048 | Y13: =(X13-AL13)/(AK13-AL13) -> 0.0053389606 | Z13: 932.1986 | AA13: =(Z13-AL13)/(AK13-AL13) -> 0 | AB13: 1616.6195 | AC13: =(AB13-AL13)/(AK13-AL13) -> 0.5142128 | AD13: 1530.3971 | AE13: =(AD13-AL13)/(AK13-AL13) -> 0.44943297 | AF13: 2147.7819 | AG13: =(AF13-AL13)/(AK13-AL13) -> 0.9132808 | AH13: 1354.8739 | AI13: =(AH13-AL13)/(AK13-AL13) -> 0.31756051 | AK13: =MAX(D13:D17,R13,T13,V13,X13,Z13,AB13,AD13,AF13,AH13) -> 2263.2058 | AL13: =MIN(D13:D17,R13,T13,V13,X13,Z13,AB13,AD13,AF13,AH13) -> 932.1986
D14: 2139.3092 | E14: 4.9931966 | G14: 79.942918 | H14: =(D14-AL14)/(AK14-AL14) -> 0.90691514 | AK14: 2263.2058 | AL14: 932.1986
D15: 2139.3092 | E15: 5.5511633 | G15: 88.8664 | H15: =(D15-AL15)/(AK15-AL15) -> 0.90691514 | AK15: 2263.2058 | AL15: 932.1986
D16: 2263.2058 | E16: 6.45366 | G16: 148.53573 | H16: =(D16-AL16)/(AK16-AL16) -> 1 | AK16: 2263.2058 | AL16: 932.1986
D17: 2139.3092 | E17: 5.9386898 | G17: 95.073317 | H17: =(D17-AL17)/(AK17-AL17) -> 0.90691514 | AK17: 2263.2058 | AL17: 932.1986
B18: Small-dominant | C18: #1 | D18: 403.79159 | E18: 4.1352143 | F18: =AVERAGE(E18:E22) -> 4.5722215 | G18: 91.034458 | H18: =(D18-AL18)/(AK18-AL18) -> 0.80854808 | I18: =AVERAGE(D18:D22) -> 507.99214 | J18: =AVERAGE(H18:H22) -> 0.86371847 | K18: =MAX(D18:D22) -> 765.38769 | L18: =MIN(D18:D22) -> 403.79159 | M18: 765.38 | N18: 0 | O18: 0.8 | P18: =M18/I18 -> 1.5066768 | R18: -334.51704 | S18: =(R18-AL18)/(AK18-AL18) -> 0.41764064 | T18: -248.36 | U18: =(T18-AL18)/(AK18-AL18) -> 0.46325765 | V18: 121.89883 | W18: =(V18-AL18)/(AK18-AL18) -> 0.65929617 | X18: 121.89883 | Y18: =(X18-AL18)/(AK18-AL18) -> 0.65929617 | Z18: 109.85869 | AA18: =(Z18-AL18)/(AK18-AL18) -> 0.65292135 | AB18: 765.38769 | AC18: =(AB18-AL18)/(AK18-AL18) -> 1 | AD18: -182.16992 | AE18: =(AD18-AL18)/(AK18-AL18) -> 0.49830288 | AF18: -1123.3168 | AG18: =(AF18-AL18)/(AK18-AL18) -> 0 | AH18: -1123.3168 | AI18: =(AH18-AL18)/(AK18-AL18) -> 0 | AK18: =MAX(D18:D22,R18,T18,V18,X18,Z18,AB18,AD18,AF18,AH18) -> 765.38769 | AL18: =MIN(D18:D22,R18,T18,V18,X18,Z18,AB18,AD18,AF18,AH18) -> -1123.3168
D19: 483.49492 | E19: 5.7190405 | G19: 120.18249 | H19: =(D19-AL19)/(AK19-AL19) -> 0.85074808 | AK19: 765.38769 | AL19: -1123.3168
D20: 403.79159 | E20: 3.866654 | G20: 85.130106 | H20: =(D20-AL20)/(AK20-AL20) -> 0.80854808 | AK20: 765.38769 | AL20: -1123.3168
D21: 765.38769 | E21: 4.3148212 | G21: 103.64133 | H21: =(D21-AL21)/(AK21-AL21) -> 1 | AK21: 765.38769 | AL21: -1123.3168
D22: 483.49492 | E22: 4.8253775 | G22: 106.23366 | H22: =(D22-AL22)/(AK22-AL22) -> 0.85074808 | AK22: 765.38769 | AL22: -1123.3168
C23: #2 | D23: 1182.1327 | E23: 4.3067316 | F23: =AVERAGE(E23:E27) -> 5.7918576 | G23: 103.4422 | H23: =(D23-AL23)/(AK23-AL23) -> 1 | I23: =AVERAGE(D23:D27) -> 1052.9653 | J23: =AVERAGE(H23:H27) -> 0.93401048 | K23: =MAX(D23:D27) -> 1182.1327 | L23: =MIN(D23:D27) -> 859.2142 | M23: 1220.05 | N23: 0 | O23: 1.13 | P23: =M23/I23 -> 1.1586802 | R23: -440.71424 | S23: =(R23-AL23)/(AK23-AL23) -> 0.17091379 | T23: 493.52204 | U23: =(T23-AL23)/(AK23-AL23) -> 0.64819998 | V23: 252.74271 | W23: =(V23-AL23)/(AK23-AL23) -> 0.52518972 | X23: 846.86398 | Y23: =(X23-AL23)/(AK23-AL23) -> 0.82871666 | Z23: 329.49379 | AA23: =(Z23-AL23)/(AK23-AL23) -> 0.56440061 | AB23: 859.2142 | AC23: =(AB23-AL23)/(AK23-AL23) -> 0.83502619 | AD23: 493.28176 | AE23: =(AD23-AL23)/(AK23-AL23) -> 0.64807723 | AF23: 480.53975 | AG23: =(AF23-AL23)/(AK23-AL23) -> 0.64156754 | AH23: -775.25957 | AI23: =(AH23-AL23)/(AK23-AL23) -> 0 | AK23: =MAX(D23:D27,R23,T23,V23,X23,Z23,AB23,AD23,AF23,AH23) -> 1182.1327 | AL23: =MIN(D23:D27,R23,T23,V23,X23,Z23,AB23,AD23,AF23,AH23) -> -775.25957
D24: 859.2142 | E24: 4.7772086 | G24: 76.485124 | H24: =(D24-AL24)/(AK24-AL24) -> 0.83502619 | AK24: 1182.1327 | AL24: -775.25957
D25: 859.2142 | E25: 5.992377 | G25: 107.92949 | H25: =(D25-AL25)/(AK25-AL25) -> 0.83502619 | AK25: 1182.1327 | AL25: -775.25957
D26: 1182.1327 | E26: 7.017463 | G26: 175.54908 | H26: =(D26-AL26)/(AK26-AL26) -> 1 | AK26: 1182.1327 | AL26: -775.25957
D27: 1182.1327 | E27: 6.8655079 | G27: 185.47126 | H27: =(D27-AL27)/(AK27-AL27) -> 1 | AK27: 1182.1327 | AL27: -775.25957
C28: #3 | D28: 665.67035 | E28: 6.4898949 | F28: =AVERAGE(E28:E32) -> 5.4612856 | G28: 103.8901 | H28: =(D28-AL28)/(AK28-AL28) -> 0.90062829 | I28: =AVERAGE(D28:D32) -> 707.51142 | J28: =AVERAGE(H28:H32) -> 0.92050263 | K28: =MAX(D28:D32) -> 874.8757 | L28: =MIN(D28:D32) -> 665.67035 | M28: 1205.59 | N28: 5e-06 | O28: 2.4 | P28: =M28/I28 -> 1.7039866 | R28: -223.80082 | S28: =(R28-AL28)/(AK28-AL28) -> 0.478133 | T28: 312.1579 | U28: =(T28-AL28)/(AK28-AL28) -> 0.73271127 | V28: 633.67723 | W28: =(V28-AL28)/(AK28-AL28) -> 0.88543168 | X28: 719.03317 | Y28: =(X28-AL28)/(AK28-AL28) -> 0.92597542 | Z28: 271.4251 | AA28: =(Z28-AL28)/(AK28-AL28) -> 0.71336335 | AB28: 763.62816 | AC28: =(AB28-AL28)/(AK28-AL28) -> 0.94715786 | AD28: 375.97168 | AE28: =(AD28-AL28)/(AK28-AL28) -> 0.76302257 | AF28: 157.43379 | AG28: =(AF28-AL28)/(AK28-AL28) -> 0.65921793 | AH28: -1230.405 | AI28: =(AH28-AL28)/(AK28-AL28) -> 0 | AK28: =MAX(D28:D32,R28,T28,V28,X28,Z28,AB28,AD28,AF28,AH28) -> 874.8757 | AL28: =MIN(D28:D32,R28,T28,V28,X28,Z28,AB28,AD28,AF28,AH28) -> -1230.405
D29: 665.67035 | E29: 5.7988854 | G29: 104.43171 | H29: =(D29-AL29)/(AK29-AL29) -> 0.90062829 | AK29: 874.8757 | AL29: -1230.405
D30: 665.67035 | E30: 5.2077911 | G30: 93.795997 | H30: =(D30-AL30)/(AK30-AL30) -> 0.90062829 | AK30: 874.8757 | AL30: -1230.405
D31: 874.8757 | E31: 4.9782428 | G31: 124.52477 | H31: =(D31-AL31)/(AK31-AL31) -> 1 | AK31: 874.8757 | AL31: -1230.405
D32: 665.67035 | E32: 4.8316137 | G32: 77.382475 | H32: =(D32-AL32)/(AK32-AL32) -> 0.90062829 | AK32: 874.8757 | AL32: -1230.405
B33: Large-dominant | C33: #1 | D33: 1213.4688 | E33: 8.9879026 | F33: =AVERAGE(E33:E37) -> 8.0978597 | G33: 143.86418 | H33: =(D33-AL33)/(AK33-AL33) -> 1 | I33: =AVERAGE(D33:D37) -> 990.77073 | J33: =AVERAGE(H33:H37) -> 0.79430499 | K33: =MAX(D33:D37) -> 1213.4688 | L33: =MIN(D33:D37) -> 847.93364 | M33: 1213.48 | N33: 0 | O33: 1.88 | P33: =M33/I33 -> 1.2247839 | R33: 477.07284 | S33: =(R33-AL33)/(AK33-AL33) -> 0.31982801 | T33: 534.78759 | U33: =(T33-AL33)/(AK33-AL33) -> 0.37313624 | V33: 847.93364 | W33: =(V33-AL33)/(AK33-AL33) -> 0.66237353 | X33: 448.12979 | Y33: =(X33-AL33)/(AK33-AL33) -> 0.29309477 | Z33: 358.12979 | AA33: =(Z33-AL33)/(AK33-AL33) -> 0.20996628 | AB33: 610.35859 | AC33: =(AB33-AL33)/(AK33-AL33) -> 0.44293738 | AD33: 852.21337 | AE33: =(AD33-AL33)/(AK33-AL33) -> 0.66632651 | AF33: 130.80741 | AG33: =(AF33-AL33)/(AK33-AL33) -> 0 | AH33: 443.95345 | AI33: =(AH33-AL33)/(AK33-AL33) -> 0.28923729 | AK33: =MAX(D33:D37,R33,T33,V33,X33,Z33,AB33,AD33,AF33,AH33) -> 1213.4688 | AL33: =MIN(D33:D37,R33,T33,V33,X33,Z33,AB33,AD33,AF33,AH33) -> 130.80741
D34: 847.93364 | E34: 6.8154665 | G34: 88.659807 | H34: =(D34-AL34)/(AK34-AL34) -> 0.66237353 | AK34: 1213.4688 | AL34: 130.80741
D35: 847.93364 | E35: 7.5895709 | G35: 91.13358 | H35: =(D35-AL35)/(AK35-AL35) -> 0.66237353 | AK35: 1213.4688 | AL35: 130.80741
D36: 847.93364 | E36: 10.315172 | G36: 144.46717 | H36: =(D36-AL36)/(AK36-AL36) -> 0.66237353 | AK36: 1213.4688 | AL36: 130.80741
D37: 1196.584 | E37: 6.7811864 | G37: 169.62026 | H37: =(D37-AL37)/(AK37-AL37) -> 0.98440435 | AK37: 1213.4688 | AL37: 130.80741
C38: #2 | D38: 1602.8047 | E38: 10.072448 | F38: =AVERAGE(E38:E42) -> 11.750516 | G38: 100.77525 | H38: =(D38-AL38)/(AK38-AL38) -> 0.79301137 | I38: =AVERAGE(D38:D42) -> 1821.0835 | J38: =AVERAGE(H38:H42) -> 0.91720455 | K38: =MAX(D38:D42) -> 1966.6027 | L38: =MIN(D38:D42) -> 1602.8047 | M38: 1966.61 | N38: 0 | O38: 1.02 | P38: =M38/I38 -> 1.079912 | R38: 942.37535 | S38: =(R38-AL38)/(AK38-AL38) -> 0.41724971 | T38: 942.37535 | U38: =(T38-AL38)/(AK38-AL38) -> 0.41724971 | V38: 1287.7049 | W38: =(V38-AL38)/(AK38-AL38) -> 0.61373037 | X38: 479.02765 | Y38: =(X38-AL38)/(AK38-AL38) -> 0.15362075 | Z38: 209.02765 | AA38: =(Z38-AL38)/(AK38-AL38) -> 0 | AB38: 942.37535 | AC38: =(AB38-AL38)/(AK38-AL38) -> 0.41724971 | AD38: 962.7707 | AE38: =(AD38-AL38)/(AK38-AL38) -> 0.42885397 | AF38: 1025.3141 | AG38: =(AF38-AL38)/(AK38-AL38) -> 0.46443902 | AH38: 233.88752 | AI38: =(AH38-AL38)/(AK38-AL38) -> 0.014144412 | AK38: =MAX(D38:D42,R38,T38,V38,X38,Z38,AB38,AD38,AF38,AH38) -> 1966.6027 | AL38: =MIN(D38:D42,R38,T38,V38,X38,Z38,AB38,AD38,AF38,AH38) -> 209.02765
D39: 1966.6027 | E39: 12.714041 | G39: 139.90721 | H39: =(D39-AL39)/(AK39-AL39) -> 1 | AK39: 1966.6027 | AL39: 209.02765
D40: 1602.8047 | E40: 11.502255 | G40: 92.055876 | H40: =(D40-AL40)/(AK40-AL40) -> 0.79301137 | AK40: 1966.6027 | AL40: 209.02765
...

Sheet T=72
A1: T | B1: Arrival | C1: Ins. ID | D1: OUR APPROACH | M1: MILP | N1: MIPGap | O1: t | P1: ECR | R1: while_available | T1: waiting buffer | AB1: full_capacity | AK1: MAX | AL1: MIN
D2: val. | E2: mcts_time | G2: sim_time | H2: RDI | I2: AVG | J2: AVG RDI | K2: MAX | L2: MIN | T2: 3 | V2: 6 | X2: 9 | Z2: 12 | AB2: 0.2 | AD2: 0.4 | AF2: 0.6 | AH2: 0.8
A3: 72 | B3: Uniform | C3: #1 | D3: 2106.3594 | E3: 8.8828084 | F3: =AVERAGE(E3:E7) -> 8.8885938 | G3: 266.57286 | H3: =(D3-AL3)/(AK3-AL3) -> 1 | I3: =AVERAGE(D3:D7) -> 1964.7125 | J3: =AVERAGE(H3:H7) -> 0.95322956 | K3: =MAX(D3:D7) -> 2106.3594 | L3: =MIN(D3:D7) -> 1782.6101 | M3: 2535.18 | N3: 0 | O3: 544.37 | P3: =M3/I3 -> 1.2903568 | R3: 1018.346 | S3: =(R3-AL3)/(AK3-AL3) -> 0.64074854 | T3: 1278.1877 | U3: =(T3-AL3)/(AK3-AL3) -> 0.72654576 | V3: 1771.9246 | W3: =(V3-AL3)/(AK3-AL3) -> 0.8895729 | X3: 847.41289 | Y3: =(X3-AL3)/(AK3-AL3) -> 0.58430809 | Z3: 821.34259 | AA3: =(Z3-AL3)/(AK3-AL3) -> 0.57569993 | AB3: 1836.5007 | AC3: =(AB3-AL3)/(AK3-AL3) -> 0.91089529 | AD3: 2065.8182 | AE3: =(AD3-AL3)/(AK3-AL3) -> 0.98661369 | AF3: 1056.0769 | AG3: =(AF3-AL3)/(AK3-AL3) -> 0.65320693 | AH3: -922.19728 | AI3: =(AH3-AL3)/(AK3-AL3) -> 0 | AK3: =MAX(D3:D7,R3,T3,V3,X3,Z3,AB3,AD3,AF3,AH3) -> 2106.3594 | AL3: =MIN(D3:D7,R3,T3,V3,X3,Z3,AB3,AD3,AF3,AH3) -> -922.19728
D4: 2039.5684 | E4: 9.1172807 | G4: 282.72432 | H4: =(D4-AL4)/(AK4-AL4) -> 0.97794626 | AK4: 2106.3594 | AL4: -922.19728
D5: 2009.5684 | E5: 10.129076 | G5: 293.82386 | H5: =(D5-AL5)/(AK5-AL5) -> 0.96804055 | AK5: 2106.3594 | AL5: -922.19728
D6: 1885.456 | E6: 7.39034 | G6: 229.18433 | H6: =(D6-AL6)/(AK6-AL6) -> 0.92705983 | AK6: 2106.3594 | AL6: -922.19728
D7: 1782.6101 | E7: 8.9234636 | G7: 357.05208 | H7: =(D7-AL7)/(AK7-AL7) -> 0.89310113 | AK7: 2106.3594 | AL7: -922.19728
C8: #2 | D8: 2934.1589 | E8: 13.910181 | F8: =AVERAGE(E8:E12) -> 12.899347 | G8: 320.00584 | H8: =(D8-AL8)/(AK8-AL8) -> 0.98631826 | I8: =AVERAGE(D8:D12) -> 2666.5235 | J8: =AVERAGE(H8:H12) -> 0.93155514 | K8: =MAX(D8:D12) -> 3001.0235 | L8: =MIN(D8:D12) -> 2413.3538 | M8: 3586.46 | N8: 0 | O8: 336.34 | P8: =M8/I8 -> 1.3449947 | R8: 1812.807 | S8: =(R8-AL8)/(AK8-AL8) -> 0.75686902 | T8: 2346.7499 | U8: =(T8-AL8)/(AK8-AL8) -> 0.86612357 | V8: 2620.0419 | W8: =(V8-AL8)/(AK8-AL8) -> 0.92204415 | X8: 2192.2101 | Y8: =(X8-AL8)/(AK8-AL8) -> 0.83450189 | Z8: 2461.9842 | AA8: =(Z8-AL8)/(AK8-AL8) -> 0.88970263 | AB8: 2264.4333 | AC8: =(AB8-AL8)/(AK8-AL8) -> 0.84928007 | AD8: 2305.6147 | AE8: =(AD8-AL8)/(AK8-AL8) -> 0.85770656 | AF8: 2480.3872 | AG8: =(AF8-AL8)/(AK8-AL8) -> 0.89346822 | AH8: -1886.1224 | AI8: =(AH8-AL8)/(AK8-AL8) -> 0 | AK8: =MAX(D8:D12,R8,T8,V8,X8,Z8,AB8,AD8,AF8,AH8) -> 3001.0235 | AL8: =MIN(D8:D12,R8,T8,V8,X8,Z8,AB8,AD8,AF8,AH8) -> -1886.1224
D9: 2557.8783 | E9: 11.721483 | G9: 187.62636 | H9: =(D9-AL9)/(AK9-AL9) -> 0.90932433 | AK9: 3001.0235 | AL9: -1886.1224
D10: 3001.0235 | E10: 13.61249 | G10: 326.77445 | H10: =(D10-AL10)/(AK10-AL10) -> 1 | AK10: 3001.0235 | AL10: -1886.1224
D11: 2426.2032 | E11: 13.185847 | G11: 211.02134 | H11: =(D11-AL11)/(AK11-AL11) -> 0.88238118 | AK11: 3001.0235 | AL11: -1886.1224
D12: 2413.3538 | E12: 12.066732 | G12: 241.39538 | H12: =(D12-AL12)/(AK12-AL12) -> 0.87975196 | AK12: 3001.0235 | AL12: -1886.1224
C13: #3 | D13: 2565.5383 | E13: 10.213507 | F13: =AVERAGE(E13:E17) -> 10.232496 | G13: 326.92379 | H13: =(D13-AL13)/(AK13-AL13) -> 0.90960797 | I13: =AVERAGE(D13:D17) -> 2706.6995 | J13: =AVERAGE(H13:H17) -> 0.9449767 | K13: =MAX(D13:D17) -> 2926.3048 | L13: =MIN(D13:D17) -> 2565.5383 | M13: 3231.46 | N13: 0 | O13: 2172.88 | P13: =M13/I13 -> 1.1938747 | R13: 1478.4028 | S13: =(R13-AL13)/(AK13-AL13) -> 0.63722012 | T13: 2202.6543 | U13: =(T13-AL13)/(AK13-AL13) -> 0.81868537 | V13: 1925.4736 | W13: =(V13-AL13)/(AK13-AL13) -> 0.74923621 | X13: 1910.3824 | Y13: =(X13-AL13)/(AK13-AL13) -> 0.74545502 | Z13: 1360.2888 | AA13: =(Z13-AL13)/(AK13-AL13) -> 0.60762602 | AB13: 2045.6539 | AC13: =(AB13-AL13)/(AK13-AL13) -> 0.77934805 | AD13: 2509.8073 | AE13: =(AD13-AL13)/(AK13-AL13) -> 0.89564425 | AF13: 708.96547 | AG13: =(AF13-AL13)/(AK13-AL13) -> 0.44443334 | AH13: -1064.8262 | AI13: =(AH13-AL13)/(AK13-AL13) -> 0 | AK13: =MAX(D13:D17,R13,T13,V13,X13,Z13,AB13,AD13,AF13,AH13) -> 2926.3048 | AL13: =MIN(D13:D17,R13,T13,V13,X13,Z13,AB13,AD13,AF13,AH13) -> -1064.8262
D14: 2589.7154 | E14: 11.11072 | G14: 333.40523 | H14: =(D14-AL14)/(AK14-AL14) -> 0.91566566 | AK14: 2926.3048 | AL14: -1064.8262
D15: 2926.3048 | E15: 10.625772 | G15: 382.63332 | H15: =(D15-AL15)/(AK15-AL15) -> 1 | AK15: 2926.3048 | AL15: -1064.8262
D16: 2708.4396 | E16: 8.6935257 | G16: 321.76698 | H16: =(D16-AL16)/(AK16-AL16) -> 0.94541267 | AK16: 2926.3048 | AL16: -1064.8262
D17: 2743.4997 | E17: 10.518956 | G17: 399.82883 | H17: =(D17-AL17)/(AK17-AL17) -> 0.95419718 | AK17: 2926.3048 | AL17: -1064.8262
B18: Small-dominant | C18: #1 | D18: 1709.8895 | E18: 14.0241 | F18: =AVERAGE(E18:E22) -> 13.125319 | G18: 308.59491 | H18: =(D18-AL18)/(AK18-AL18) -> 0.97459121 | I18: =AVERAGE(D18:D22) -> 1613.8775 | J18: =AVERAGE(H18:H22) -> 0.960561 | K18: =MAX(D18:D22) -> 1883.7679 | L18: =MIN(D18:D22) -> 1068.1981 | M18: 2721.11 | N18: 0.13313 | O18: 3601.87 | R18: 966.66661 | S18: =(R18-AL18)/(AK18-AL18) -> 0.86598431 | T18: 498.41036 | U18: =(T18-AL18)/(AK18-AL18) -> 0.79755819 | V18: 1458.3734 | W18: =(V18-AL18)/(AK18-AL18) -> 0.93783725 | X18: 847.462 | Y18: =(X18-AL18)/(AK18-AL18) -> 0.84856498 | Z18: 1370.9337 | AA18: =(Z18-AL18)/(AK18-AL18) -> 0.92505971 | AB18: 860.89209 | AC18: =(AB18-AL18)/(AK18-AL18) -> 0.85052751 | AD18: 885.81592 | AE18: =(AD18-AL18)/(AK18-AL18) -> 0.85416962 | AF18: -2700.9415 | AG18: =(AF18-AL18)/(AK18-AL18) -> 0.33003802 | AH18: -4959.4704 | AI18: =(AH18-AL18)/(AK18-AL18) -> 0 | AK18: =MAX(D18:D22,R18,T18,V18,X18,Z18,AB18,AD18,AF18,AH18) -> 1883.7679 | AL18: =MIN(D18:D22,R18,T18,V18,X18,Z18,AB18,AD18,AF18,AH18) -> -4959.4704
D19: 1709.8895 | E19: 14.602932 | G19: 292.11638 | H19: =(D19-AL19)/(AK19-AL19) -> 0.97459121 | AK19: 1883.7679 | AL19: -4959.4704
D20: 1883.7679 | E20: 13.196659 | G20: 277.19057 | H20: =(D20-AL20)/(AK20-AL20) -> 1 | AK20: 1883.7679 | AL20: -4959.4704
D21: 1068.1981 | E21: 10.956579 | G21: 295.9033 | H21: =(D21-AL21)/(AK21-AL21) -> 0.88082108 | AK21: 1883.7679 | AL21: -4959.4704
D22: 1697.6422 | E22: 12.846327 | G22: 385.47245 | H22: =(D22-AL22)/(AK22-AL22) -> 0.97280151 | AK22: 1883.7679 | AL22: -4959.4704
C23: #2 | D23: 2208.1832 | E23: 11.772533 | F23: =AVERAGE(E23:E27) -> 11.804266 | G23: 294.38203 | H23: =(D23-AL23)/(AK23-AL23) -> 0.76339192 | I23: =AVERAGE(D23:D27) -> 2444.2814 | J23: =AVERAGE(H23:H27) -> 0.83232368 | K23: =MAX(D23:D27) -> 3018.5898 | L23: =MIN(D23:D27) -> 1941.2759 | M23: 3643.28 | N23: 0 | O23: 62.17 | P23: =M23/I23 -> 1.4905321 | R23: 1214.0427 | S23: =(R23-AL23)/(AK23-AL23) -> 0.47314049 | T23: 1926.6125 | U23: =(T23-AL23)/(AK23-AL23) -> 0.68118392 | V23: 1824.1942 | W23: =(V23-AL23)/(AK23-AL23) -> 0.65128166 | X23: 1134.3854 | Y23: =(X23-AL23)/(AK23-AL23) -> 0.44988356 | Z23: 941.16919 | AA23: =(Z23-AL23)/(AK23-AL23) -> 0.39347173 | AB23: 2843.4813 | AC23: =(AB23-AL23)/(AK23-AL23) -> 0.94887495 | AD23: 2893.4684 | AE23: =(AD23-AL23)/(AK23-AL23) -> 0.96346929 | AF23: -406.51124 | AG23: =(AF23-AL23)/(AK23-AL23) -> 0 | AH23: 157.22119 | AI23: =(AH23-AL23)/(AK23-AL23) -> 0.16458856 | AK23: =MAX(D23:D27,R23,T23,V23,X23,Z23,AB23,AD23,AF23,AH23) -> 3018.5898 | AL23: =MIN(D23:D27,R23,T23,V23,X23,Z23,AB23,AD23,AF23,AH23) -> -406.51124
D24: 3018.5898 | E24: 9.4248556 | G24: 348.82918 | H24: =(D24-AL24)/(AK24-AL24) -> 1 | AK24: 3018.5898 | AL24: -406.51124
D25: 2721.1798 | E25: 9.4774193 | G25: 303.39291 | H25: =(D25-AL25)/(AK25-AL25) -> 0.91316753 | AK25: 3018.5898 | AL25: -406.51124
D26: 2332.1785 | E26: 14.617537 | G26: 277.79692 | H26: =(D26-AL26)/(AK26-AL26) -> 0.79959385 | AK26: 3018.5898 | AL26: -406.51124
D27: 1941.2759 | E27: 13.728983 | G27: 260.90941 | H27: =(D27-AL27)/(AK27-AL27) -> 0.68546509 | AK27: 3018.5898 | AL27: -406.51124
C28: #3 | D28: 2521.1319 | E28: 11.211153 | F28: =AVERAGE(E28:E32) -> 11.73973 | G28: 426.12935 | H28: =(D28-AL28)/(AK28-AL28) -> 0.91600321 | I28: =AVERAGE(D28:D32) -> 2651.1348 | J28: =AVERAGE(H28:H32) -> 0.95601 | K28: =MAX(D28:D32) -> 2794.0812 | L28: =MIN(D28:D32) -> 2516.1745 | M28: 3008.22 | N28: 0 | O28: 2811.38 | P28: =M28/I28 -> 1.1346915 | R28: 1084.2471 | S28: =(R28-AL28)/(AK28-AL28) -> 0.47381954 | T28: 2060.0478 | U28: =(T28-AL28)/(AK28-AL28) -> 0.77411024 | V28: 1858.8071 | W28: =(V28-AL28)/(AK28-AL28) -> 0.71218089 | X28: 2408.7132 | Y28: =(X28-AL28)/(AK28-AL28) -> 0.88140775 | Z28: 1418.1159 | AA28: =(Z28-AL28)/(AK28-AL28) -> 0.57656356 | AB28: 2557.4314 | AC28: =(AB28-AL28)/(AK28-AL28) -> 0.92717394 | AD28: 2204.7581 | AE28: =(AD28-AL28)/(AK28-AL28) -> 0.81864307 | AF28: 1862.577 | AG28: =(AF28-AL28)/(AK28-AL28) -> 0.71334102 | AH28: -455.43911 | AI28: =(AH28-AL28)/(AK28-AL28) -> 0 | AK28: =MAX(D28:D32,R28,T28,V28,X28,Z28,AB28,AD28,AF28,AH28) -> 2794.0812 | AL28: =MIN(D28:D32,R28,T28,V28,X28,Z28,AB28,AD28,AF28,AH28) -> -455.43911
D29: 2516.1745 | E29: 13.56773 | G29: 393.54682 | H29: =(D29-AL29)/(AK29-AL29) -> 0.91447763 | AK29: 2794.0812 | AL29: -455.43911
D30: 2675.3349 | E30: 11.456942 | G30: 424.00347 | H30: =(D30-AL30)/(AK30-AL30) -> 0.9634573 | AK30: 2794.0812 | AL30: -455.43911
D31: 2748.9514 | E31: 11.650012 | G31: 431.15195 | H31: =(D31-AL31)/(AK31-AL31) -> 0.98611188 | AK31: 2794.0812 | AL31: -455.43911
D32: 2794.0812 | E32: 10.812813 | G32: 410.98945 | H32: =(D32-AL32)/(AK32-AL32) -> 1 | AK32: 2794.0812 | AL32: -455.43911
B33: Large-dominant | C33: #1 | D33: 4079.5388 | E33: 15.049306 | F33: =AVERAGE(E33:E37) -> 12.661219 | G33: 331.15143 | H33: =(D33-AL33)/(AK33-AL33) -> 0.98376349 | I33: =AVERAGE(D33:D37) -> 3859.6598 | J33: =AVERAGE(H33:H37) -> 0.88269634 | K33: =MAX(D33:D37) -> 4079.5388 | L33: =MIN(D33:D37) -> 3713.6444 | M33: 4852.88 | N33: 0 | O33: 396.15 | P33: =M33/I33 -> 1.2573336 | R33: 3157.6019 | S33: =(R33-AL33)/(AK33-AL33) -> 0.55999608 | T33: 3116.4641 | U33: =(T33-AL33)/(AK33-AL33) -> 0.5410871 | V33: 3145.5382 | W33: =(V33-AL33)/(AK33-AL33) -> 0.55445099 | X33: 1939.2897 | Y33: =(X33-AL33)/(AK33-AL33) -> 0 | Z33: 3089.079 | AA33: =(Z33-AL33)/(AK33-AL33) -> 0.5284996 | AB33: 3531.7532 | AC33: =(AB33-AL33)/(AK33-AL33) -> 0.73197436 | AD33: 3994.7257 | AE33: =(AD33-AL33)/(AK33-AL33) -> 0.94477924 | AF33: 4114.8625 | AG33: =(AF33-AL33)/(AK33-AL33) -> 1 | AH33: 3047.1581 | AI33: =(AH33-AL33)/(AK33-AL33) -> 0.50923067 | AK33: =MAX(D33:D37,R33,T33,V33,X33,Z33,AB33,AD33,AF33,AH33) -> 4114.8625 | AL33: =MIN(D33:D37,R33,T33,V33,X33,Z33,AB33,AD33,AF33,AH33) -> 1939.2897
D34: 3945.173 | E34: 12.716359 | G34: 317.97669 | H34: =(D34-AL34)/(AK34-AL34) -> 0.92200241 | AK34: 4114.8625 | AL34: 1939.2897
D35: 3753.5825 | E35: 12.963188 | G35: 233.38916 | H35: =(D35-AL35)/(AK35-AL35) -> 0.83393798 | AK35: 4114.8625 | AL35: 1939.2897
D36: 3713.6444 | E36: 12.726064 | G36: 254.57705 | H36: =(D36-AL36)/(AK36-AL36) -> 0.81558048 | AK36: 4114.8625 | AL36: 1939.2897
D37: 3806.3605 | E37: 9.8511751 | G37: 295.62686 | H37: =(D37-AL37)/(AK37-AL37) -> 0.85819734 | AK37: 4114.8625 | AL37: 1939.2897
C38: #2 | D38: 3124.673 | E38: 11.393358 | F38: =AVERAGE(E38:E42) -> 10.738962 | G38: 262.11195 | H38: =(D38-AL38)/(AK38-AL38) -> 1 | I38: =AVERAGE(D38:D42) -> 2960.7472 | J38: =AVERAGE(H38:H42) -> 0.95110414 | K38: =MAX(D38:D42) -> 3124.673 | L38: =MIN(D38:D42) -> 2725.2878 | M38: 3718.22 | N38: 0.087377 | O38: 3602.66 | R38: 2058.7592 | S38: =(R38-AL38)/(AK38-AL38) -> 0.68205883 | T38: 2510.3406 | U38: =(T38-AL38)/(AK38-AL38) -> 0.81675672 | V38: 2829.24 | W38: =(V38-AL38)/(AK38-AL38) -> 0.91187813 | X38: 2601.7508 | Y38: =(X38-AL38)/(AK38-AL38) -> 0.84402256 | Z38: 2503.7921 | AA38: =(Z38-AL38)/(AK38-AL38) -> 0.81480343 | AB38: 2505.4224 | AC38: =(AB38-AL38)/(AK38-AL38) -> 0.81528969 | AD38: 2591.0068 | AE38: =(AD38-AL38)/(AK38-AL38) -> 0.84081786 | AF38: 2409.4444 | AG38: =(AF38-AL38)/(AK38-AL38) -> 0.78666136 | AH38: -227.87751 | AI38: =(AH38-AL38)/(AK38-AL38) -> 0 | AK38: =MAX(D38:D42,R38,T38,V38,X38,Z38,AB38,AD38,AF38,AH38) -> 3124.673 | AL38: =MIN(D38:D42,R38,T38,V38,X38,Z38,AB38,AD38,AF38,AH38) -> -227.87751
D39: 2725.2878 | E39: 10.721579 | G39: 214.48535 | H39: =(D39-AL39)/(AK39-AL39) -> 0.88087123 | AK39: 3124.673 | AL39: -227.87751
D40: 3092.3538 | E40: 10.63541 | G40: 244.68015 | H40: =(D40-AL40)/(AK40-AL40) -> 0.99035981 | AK40: 3124.673 | AL40: -227.87751
...

Sheet T=144
A1: T | B1: Arrival | C1: Ins. ID | D1: OUR APPROACH | M1: MILP | N1: MIPGap | O1: t | P1: ECR | R1: while_available | T1: waiting buffer | AB1: full_capacity | AK1: MAX | AL1: MIN
D2: val. | E2: mcts_time | G2: sim_time | H2: RDI | I2: AVG | J2: AVG RDI | K2: MAX | L2: MIN | T2: 3 | V2: 6 | X2: 9 | Z2: 12 | AB2: 0.2 | AD2: 0.4 | AF2: 0.6 | AH2: 0.8
A3: 144 | B3: Uniform | C3: #1 | D3: 6657.3556 | E3: 21.314876 | F3: =AVERAGE(E3:E7) -> 20.676991 | G3: 767.43609 | H3: =(D3-AL3)/(AK3-AL3) -> 0.95654176 | I3: =AVERAGE(D3:D7) -> 6717.85 | J3: =AVERAGE(H3:H7) -> 0.96481754 | K3: =MAX(D3:D7) -> 6975.0272 | L3: =MIN(D3:D7) -> 6550.0395 | M3: 7399.36 | N3: 0.273962 | O3: 3602.16 | R3: 5546.5893 | S3: =(R3-AL3)/(AK3-AL3) -> 0.80458623 | T3: 6276.1223 | U3: =(T3-AL3)/(AK3-AL3) -> 0.90438812 | V3: 5615.0706 | W3: =(V3-AL3)/(AK3-AL3) -> 0.81395462 | X3: 4475.7267 | Y3: =(X3-AL3)/(AK3-AL3) -> 0.65808961 | Z3: -334.78417 | AA3: =(Z3-AL3)/(AK3-AL3) -> 0 | AB3: 6099.6573 | AC3: =(AB3-AL3)/(AK3-AL3) -> 0.88024727 | AD3: 5852.8333 | AE3: =(AD3-AL3)/(AK3-AL3) -> 0.84648114 | AF3: 5763.8521 | AG3: =(AF3-AL3)/(AK3-AL3) -> 0.83430831 | AH3: 1185.7568 | AI3: =(AH3-AL3)/(AK3-AL3) -> 0.20801371 | AK3: =MAX(D3:D7,R3,T3,V3,X3,Z3,AB3,AD3,AF3,AH3) -> 6975.0272 | AL3: =MIN(D3:D7,R3,T3,V3,X3,Z3,AB3,AD3,AF3,AH3) -> -334.78417
D4: 6550.0395 | E4: 19.975937 | G4: 739.2182 | H4: =(D4-AL4)/(AK4-AL4) -> 0.94186066 | AK4: 6975.0272 | AL4: -334.78417
D5: 6975.0272 | E5: 22.192791 | G5: 799.04202 | H5: =(D5-AL5)/(AK5-AL5) -> 1 | AK5: 6975.0272 | AL5: -334.78417
D6: 6733.21 | E6: 19.311667 | G6: 598.75626 | H6: =(D6-AL6)/(AK6-AL6) -> 0.96691883 | AK6: 6975.0272 | AL6: -334.78417
D7: 6673.6176 | E7: 20.589686 | G7: 658.96552 | H7: =(D7-AL7)/(AK7-AL7) -> 0.95876644 | AK7: 6975.0272 | AL7: -334.78417
C8: #2 | D8: 6629.534 | E8: 22.166976 | F8: =AVERAGE(E8:E12) -> 23.486138 | G8: 886.78957 | H8: =(D8-AL8)/(AK8-AL8) -> 0.9276523 | I8: =AVERAGE(D8:D12) -> 6753.3482 | J8: =AVERAGE(H8:H12) -> 0.95919181 | K8: =MAX(D8:D12) -> 6913.5484 | L8: =MIN(D8:D12) -> 6629.534 | M8: 7753.62 | N8: 0.203802 | O8: 3603.4 | R8: 5938.63 | S8: =(R8-AL8)/(AK8-AL8) -> 0.75165663 | T8: 6240.8953 | U8: =(T8-AL8)/(AK8-AL8) -> 0.82865342 | V8: 4845.2592 | W8: =(V8-AL8)/(AK8-AL8) -> 0.47313956 | X8: 3679.8469 | Y8: =(X8-AL8)/(AK8-AL8) -> 0.17627122 | Z8: 2987.8613 | AA8: =(Z8-AL8)/(AK8-AL8) -> 0 | AB8: 6283.0211 | AC8: =(AB8-AL8)/(AK8-AL8) -> 0.83938422 | AD8: 5909.0404 | AE8: =(AD8-AL8)/(AK8-AL8) -> 0.74411918 | AF8: 5025.9772 | AG8: =(AF8-AL8)/(AK8-AL8) -> 0.51917432 | AH8: 3120.8865 | AI8: =(AH8-AL8)/(AK8-AL8) -> 0.033885835 | AK8: =MAX(D8:D12,R8,T8,V8,X8,Z8,AB8,AD8,AF8,AH8) -> 6913.5484 | AL8: =MIN(D8:D12,R8,T8,V8,X8,Z8,AB8,AD8,AF8,AH8) -> 2987.8613
D9: 6653.9626 | E9: 23.336375 | G9: 1260.3096 | H9: =(D9-AL9)/(AK9-AL9) -> 0.93387507 | AK9: 6913.5484 | AL9: 2987.8613
D10: 6754.7244 | E10: 26.929515 | G10: 1185.0201 | H10: =(D10-AL10)/(AK10-AL10) -> 0.95954236 | AK10: 6913.5484 | AL10: 2987.8613
D11: 6913.5484 | E11: 24.443521 | G11: 953.40882 | H11: =(D11-AL11)/(AK11-AL11) -> 1 | AK11: 6913.5484 | AL11: 2987.8613
D12: 6814.9716 | E12: 20.554301 | G12: 883.95542 | H12: =(D12-AL12)/(AK12-AL12) -> 0.9748893 | AK12: 6913.5484 | AL12: 2987.8613
C13: #3 | D13: 4724.5203 | E13: 20.249946 | F13: =AVERAGE(E13:E17) -> 21.166088 | G13: 1093.6414 | H13: =(D13-AL13)/(AK13-AL13) -> 0.95808988 | I13: =AVERAGE(D13:D17) -> 4682.9414 | J13: =AVERAGE(H13:H17) -> 0.95283138 | K13: =MAX(D13:D17) -> 5055.9036 | L13: =MIN(D13:D17) -> 4534.0374 | M13: 6357.04 | N13: 0.254862 | O13: 3613.72 | R13: 3454.0175 | S13: =(R13-AL13)/(AK13-AL13) -> 0.79740907 | T13: 3778.705 | U13: =(T13-AL13)/(AK13-AL13) -> 0.83847238 | V13: 3622.2526 | W13: =(V13-AL13)/(AK13-AL13) -> 0.81868581 | X13: 3597.4936 | Y13: =(X13-AL13)/(AK13-AL13) -> 0.81555452 | Z13: 2129.1308 | AA13: =(Z13-AL13)/(AK13-AL13) -> 0.62985032 | AB13: 4346.6096 | AC13: =(AB13-AL13)/(AK13-AL13) -> 0.91029542 | AD13: 3521.6181 | AE13: =(AD13-AL13)/(AK13-AL13) -> 0.80595854 | AF13: 1066.8964 | AG13: =(AF13-AL13)/(AK13-AL13) -> 0.49550927 | AH13: -2851.0944 | AI13: =(AH13-AL13)/(AK13-AL13) -> 0 | AK13: =MAX(D13:D17,R13,T13,V13,X13,Z13,AB13,AD13,AF13,AH13) -> 5055.9036 | AL13: =MIN(D13:D17,R13,T13,V13,X13,Z13,AB13,AD13,AF13,AH13) -> -2851.0944
D14: 4541.1179 | E14: 24.381741 | G14: 1194.8377 | H14: =(D14-AL14)/(AK14-AL14) -> 0.93489493 | AK14: 5055.9036 | AL14: -2851.0944
D15: 4559.1278 | E15: 20.907207 | G15: 1191.8592 | H15: =(D15-AL15)/(AK15-AL15) -> 0.93717265 | AK15: 5055.9036 | AL15: -2851.0944
D16: 5055.9036 | E16: 19.587762 | G16: 1097.066 | H16: =(D16-AL16)/(AK16-AL16) -> 1 | AK16: 5055.9036 | AL16: -2851.0944
D17: 4534.0374 | E17: 20.703786 | G17: 1076.7422 | H17: =(D17-AL17)/(AK17-AL17) -> 0.93399945 | AK17: 5055.9036 | AL17: -2851.0944
B18: Small-dominant | C18: #1 | D18: 4335.7034 | E18: 18.406382 | F18: =AVERAGE(E18:E22) -> 20.452101 | G18: 828.40469 | H18: =(D18-AL18)/(AK18-AL18) -> 0.99449106 | I18: =AVERAGE(D18:D22) -> 4248.1293 | J18: =AVERAGE(H18:H22) -> 0.97966756 | K18: =MAX(D18:D22) -> 4368.249 | L18: =MIN(D18:D22) -> 4082.7228 | M18: 5627.55 | N18: 0.350653 | O18: 3602.17 | R18: 2635.2987 | S18: =(R18-AL18)/(AK18-AL18) -> 0.70666647 | T18: 3646.2439 | U18: =(T18-AL18)/(AK18-AL18) -> 0.87778744 | V18: 3299.823 | W18: =(V18-AL18)/(AK18-AL18) -> 0.81914937 | X18: 3336.2775 | Y18: =(X18-AL18)/(AK18-AL18) -> 0.82531996 | Z18: 1881.1272 | AA18: =(Z18-AL18)/(AK18-AL18) -> 0.57900915 | AB18: 3914.5307 | AC18: =(AB18-AL18)/(AK18-AL18) -> 0.92319988 | AD18: 1383.6089 | AE18: =(AD18-AL18)/(AK18-AL18) -> 0.49479508 | AF18: 343.73844 | AG18: =(AF18-AL18)/(AK18-AL18) -> 0.31877798 | AH18: -1539.532 | AI18: =(AH18-AL18)/(AK18-AL18) -> 0 | AK18: =MAX(D18:D22,R18,T18,V18,X18,Z18,AB18,AD18,AF18,AH18) -> 4368.249 | AL18: =MIN(D18:D22,R18,T18,V18,X18,Z18,AB18,AD18,AF18,AH18) -> -1539.532
D19: 4368.249 | E19: 19.40217 | G19: 737.38801 | H19: =(D19-AL19)/(AK19-AL19) -> 1 | AK19: 4368.249 | AL19: -1539.532
D20: 4126.2296 | E20: 20.23354 | G20: 971.33838 | H20: =(D20-AL20)/(AK20-AL20) -> 0.9590338 | AK20: 4368.249 | AL20: -1539.532
D21: 4082.7228 | E21: 20.125237 | G21: 805.118 | H21: =(D21-AL21)/(AK21-AL21) -> 0.95166948 | AK21: 4368.249 | AL21: -1539.532
D22: 4327.7419 | E22: 24.093179 | G22: 1060.2163 | H22: =(D22-AL22)/(AK22-AL22) -> 0.99314345 | AK22: 4368.249 | AL22: -1539.532
C23: #2 | D23: 5427.3829 | E23: 22.917243 | F23: =AVERAGE(E23:E27) -> 21.193193 | G23: 893.88501 | H23: =(D23-AL23)/(AK23-AL23) -> 0.96191885 | I23: =AVERAGE(D23:D27) -> 5671.9351 | J23: =AVERAGE(H23:H27) -> 0.97889016 | K23: =MAX(D23:D27) -> 5976.1223 | L23: =MIN(D23:D27) -> 5427.3829 | M23: 6989.95 | N23: 0.259859 | O23: 3601.99 | R23: 4453.3954 | S23: =(R23-AL23)/(AK23-AL23) -> 0.89432654 | T23: 5074.3522 | U23: =(T23-AL23)/(AK23-AL23) -> 0.9374194 | V23: 4139.8949 | W23: =(V23-AL23)/(AK23-AL23) -> 0.87257038 | X23: 3493.3557 | Y23: =(X23-AL23)/(AK23-AL23) -> 0.82770217 | Z23: 3759.8115 | AA23: =(Z23-AL23)/(AK23-AL23) -> 0.84619354 | AB23: 4197.8254 | AC23: =(AB23-AL23)/(AK23-AL23) -> 0.87659062 | AD23: 4653.1306 | AE23: =(AD23-AL23)/(AK23-AL23) -> 0.90818767 | AF23: 1081.9186 | AG23: =(AF23-AL23)/(AK23-AL23) -> 0.66035443 | AH23: -8433.6161 | AI23: =(AH23-AL23)/(AK23-AL23) -> 0 | AK23: =MAX(D23:D27,R23,T23,V23,X23,Z23,AB23,AD23,AF23,AH23) -> 5976.1223 | AL23: =MIN(D23:D27,R23,T23,V23,X23,Z23,AB23,AD23,AF23,AH23) -> -8433.6161
D24: 5976.1223 | E24: 20.193782 | G24: 828.05758 | H24: =(D24-AL24)/(AK24-AL24) -> 1 | AK24: 5976.1223 | AL24: -8433.6161
D25: 5733.1576 | E25: 22.836049 | G25: 1050.5827 | H25: =(D25-AL25)/(AK25-AL25) -> 0.98313885 | AK25: 5976.1223 | AL25: -8433.6161
D26: 5647.7432 | E26: 19.652426 | G26: 766.55275 | H26: =(D26-AL26)/(AK26-AL26) -> 0.97721131 | AK26: 5976.1223 | AL26: -8433.6161
D27: 5575.2693 | E27: 20.366464 | G27: 794.40163 | H27: =(D27-AL27)/(AK27-AL27) -> 0.9721818 | AK27: 5976.1223 | AL27: -8433.6161
C28: #3 | D28: 3293.7403 | E28: 20.999292 | F28: =AVERAGE(E28:E32) -> 21.381728 | G28: 1281.1141 | H28: =(D28-AL28)/(AK28-AL28) -> 0.95268862 | I28: =AVERAGE(D28:D32) -> 3406.0873 | J28: =AVERAGE(H28:H32) -> 0.96537453 | K28: =MAX(D28:D32) -> 3712.7319 | L28: =MIN(D28:D32) -> 3287.8723 | M28: 4497.08 | N28: 0.309657 | O28: 3608.29 | R28: 1189.6518 | S28: =(R28-AL28)/(AK28-AL28) -> 0.71510074 | T28: 2571.2422 | U28: =(T28-AL28)/(AK28-AL28) -> 0.87110612 | V28: 3121.0998 | W28: =(V28-AL28)/(AK28-AL28) -> 0.93319453 | X28: 2551.3211 | Y28: =(X28-AL28)/(AK28-AL28) -> 0.86885669 | Z28: 2197.4016 | AA28: =(Z28-AL28)/(AK28-AL28) -> 0.82889307 | AB28: 2995.8901 | AC28: =(AB28-AL28)/(AK28-AL28) -> 0.9190562 | AD28: 3375.2656 | AE28: =(AD28-AL28)/(AK28-AL28) -> 0.96189423 | AF28: -1846.0792 | AG28: =(AF28-AL28)/(AK28-AL28) -> 0.37231436 | AH28: -5143.3112 | AI28: =(AH28-AL28)/(AK28-AL28) -> 0 | AK28: =MAX(D28:D32,R28,T28,V28,X28,Z28,AB28,AD28,AF28,AH28) -> 3712.7319 | AL28: =MIN(D28:D32,R28,T28,V28,X28,Z28,AB28,AD28,AF28,AH28) -> -5143.3112
D29: 3305.2803 | E29: 22.723414 | G29: 1295.3939 | H29: =(D29-AL29)/(AK29-AL29) -> 0.95399169 | AK29: 3712.7319 | AL29: -5143.3112
D30: 3712.7319 | E30: 21.740545 | G30: 1282.8505 | H30: =(D30-AL30)/(AK30-AL30) -> 1 | AK30: 3712.7319 | AL30: -5143.3112
D31: 3287.8723 | E31: 18.422368 | G31: 1252.9009 | H31: =(D31-AL31)/(AK31-AL31) -> 0.95202602 | AK31: 3712.7319 | AL31: -5143.3112
D32: 3430.8116 | E32: 23.023019 | G32: 1427.5785 | H32: =(D32-AL32)/(AK32-AL32) -> 0.96816633 | AK32: 3712.7319 | AL32: -5143.3112
B33: Large-dominant | C33: #1 | D33: 5415.4307 | E33: 25.894643 | F33: =AVERAGE(E33:E37) -> 22.854235 | G33: 1139.4818 | H33: =(D33-AL33)/(AK33-AL33) -> 0.94526308 | I33: =AVERAGE(D33:D37) -> 5507.1429 | J33: =AVERAGE(H33:H37) -> 0.96337617 | K33: =MAX(D33:D37) -> 5692.5806 | L33: =MIN(D33:D37) -> 5283.3793 | M33: 6912.11 | N33: 0.294781 | O33: 3619.28 | R33: 3860.7761 | S33: =(R33-AL33)/(AK33-AL33) -> 0.63821986 | T33: 5363.6806 | U33: =(T33-AL33)/(AK33-AL33) -> 0.93504247 | V33: 4926.0834 | W33: =(V33-AL33)/(AK33-AL33) -> 0.84861732 | X33: 2384.793 | Y33: =(X33-AL33)/(AK33-AL33) -> 0.34671419 | Z33: 1325.9046 | AA33: =(Z33-AL33)/(AK33-AL33) -> 0.13758445 | AB33: 5340.7775 | AC33: =(AB33-AL33)/(AK33-AL33) -> 0.93051912 | AD33: 5208.5694 | AE33: =(AD33-AL33)/(AK33-AL33) -> 0.90440811 | AF33: 2997.472 | AG33: =(AF33-AL33)/(AK33-AL33) -> 0.46771787 | AH33: 629.27206 | AI33: =(AH33-AL33)/(AK33-AL33) -> 0 | AK33: =MAX(D33:D37,R33,T33,V33,X33,Z33,AB33,AD33,AF33,AH33) -> 5692.5806 | AL33: =MIN(D33:D37,R33,T33,V33,X33,Z33,AB33,AD33,AF33,AH33) -> 629.27206
D34: 5476.9017 | E34: 23.038111 | G34: 1175.0761 | H34: =(D34-AL34)/(AK34-AL34) -> 0.95740357 | AK34: 5692.5806 | AL34: 629.27206
D35: 5692.5806 | E35: 22.219099 | G35: 1044.4321 | H35: =(D35-AL35)/(AK35-AL35) -> 1 | AK35: 5692.5806 | AL35: 629.27206
D36: 5667.422 | E36: 22.397612 | G36: 1164.8122 | H36: =(D36-AL36)/(AK36-AL36) -> 0.99503119 | AK36: 5692.5806 | AL36: 629.27206
D37: 5283.3793 | E37: 20.721708 | G37: 932.60032 | H37: =(D37-AL37)/(AK37-AL37) -> 0.91918302 | AK37: 5692.5806 | AL37: 629.27206
C38: #2 | D38: 8057.4938 | E38: 20.45455 | F38: =AVERAGE(E38:E42) -> 19.382018 | G38: 777.37843 | H38: =(D38-AL38)/(AK38-AL38) -> 0.96572396 | I38: =AVERAGE(D38:D42) -> 8286.3502 | J38: =AVERAGE(H38:H42) -> 0.98169117 | K38: =MAX(D38:D42) -> 8548.7686 | L38: =MIN(D38:D42) -> 8057.4938 | M38: 7781.44 | N38: 0.491907 | O38: 3601.61 | R38: 6974.2097 | S38: =(R38-AL38)/(AK38-AL38) -> 0.89014369 | T38: 7930.7674 | U38: =(T38-AL38)/(AK38-AL38) -> 0.95688231 | V38: 3963.0671 | W38: =(V38-AL38)/(AK38-AL38) -> 0.68005754 | X38: 1820.0156 | Y38: =(X38-AL38)/(AK38-AL38) -> 0.53053775 | Z38: -5784.1261 | AA38: =(Z38-AL38)/(AK38-AL38) -> 0 | AB38: 7648.5417 | AC38: =(AB38-AL38)/(AK38-AL38) -> 0.93719154 | AD38: 7397.6033 | AE38: =(AD38-AL38)/(AK38-AL38) -> 0.91968368 | AF38: 7439.4898 | AG38: =(AF38-AL38)/(AK38-AL38) -> 0.92260608 | AH38: 3974.4162 | AI38: =(AH38-AL38)/(AK38-AL38) -> 0.68084937 | AK38: =MAX(D38:D42,R38,T38,V38,X38,Z38,AB38,AD38,AF38,AH38) -> 8548.7686 | AL38: =MIN(D38:D42,R38,T38,V38,X38,Z38,AB38,AD38,AF38,AH38) -> -5784.1261
D39: 8356.4681 | E39: 16.615838 | G39: 664.74206 | H39: =(D39-AL39)/(AK39-AL39) -> 0.98658327 | AK39: 8548.7686 | AL39: -5784.1261
D40: 8273.6693 | E40: 20.720821 | G40: 642.4281 | H40: =(D40-AL40)/(AK40-AL40) -> 0.98080643 | AK40: 8548.7686 | AL40: -5784.1261
...

Sheet sum up
B1: Ours | D1: while_available | F1: PWB | N1: full_capacity | W1: ECR
F2: 3 | H2: 6 | J2: 9 | L2: 12 | N2: 0.2 | P2: 0.4 | R2: 0.6 | T2: 0.8
A3: AVG | B3: =AVERAGE('T=36'!I49,'T=72'!I49,'T=144'!I49) -> 3132.7064 | C3: =AVERAGE('T=36'!J49,'T=72'!J49,'T=144'!J49) -> 0.92560536 | D3: =AVERAGE('T=36'!R49,'T=72'!R49,'T=144'!R49) -> 1978.6487 | E3: =AVERAGE('T=36'!S49,'T=72'!S49,'T=144'!S49) -> 0.55444513 | F3: =AVERAGE('T=36'!T49,'T=72'!T49,'T=144'!T49) -> 2521.6674 | G3: =AVERAGE('T=36'!U49,'T=72'!U49,'T=144'!U49) -> 0.69939992 | H3: =AVERAGE('T=36'!V49,'T=72'!V49,'T=144'!V49) -> 2378.7034 | I3: =AVERAGE('T=36'!W49,'T=72'!W49,'T=144'!W49) -> 0.72762319 | J3: =AVERAGE('T=36'!X49,'T=72'!X49,'T=144'!X49) -> 1761.9455 | K3: =AVERAGE('T=36'!Y49,'T=72'!Y49,'T=144'!Y49) -> 0.56735417 | ... U3: =AVERAGE('T=36'!AI49,'T=72'!AI49,'T=144'!AI49) -> 0.10714813 | W3: =AVERAGE('T=36'!P3:P47,'T=72'!P3:P47) -> 1.2718311
