Workbook

Sheet calibration_results_251204_36
A1: Instance_ID | B1: T_horizon | C1: Arrival_type | D1: C_opr | E1: loose_factor | F1: K_fine | G1: random_seed | H1: SAMPLING_THRESHOLD | I1: exploration_factor | J1: replication_id | K1: profit | L1: RDI | M1: MAX | N1: MIN
A2: 1 | B2: 36 | C2: Uniform | D2: 300 | E2: 3 | F2: 30 | G2: 42 | H2: 5 | I2: 5 | J2: 1 | K2: 686.90693 | L2: =(K2-N2)/(M2-N2) -> 0.49877595 | M2: =MAX(K2:K46) -> 1047.752 | N2: =MIN(K2:K46) -> 327.82432
A3: 1 | B3: 36 | C3: Uniform | D3: 300 | E3: 3 | F3: 30 | G3: 42 | H3: 5 | I3: 5 | J3: 2 | K3: 851.79367 | L3: =(K3-N3)/(M3-N3) -> 0.72780832 | M3: 1047.752 | N3: 327.82432
A4: 1 | B4: 36 | C4: Uniform | D4: 300 | E4: 3 | F4: 30 | G4: 42 | H4: 5 | I4: 5 | J4: 3 | K4: 686.90693 | L4: =(K4-N4)/(M4-N4) -> 0.49877595 | M4: 1047.752 | N4: 327.82432
A5: 1 | B5: 36 | C5: Uniform | D5: 300 | E5: 3 | F5: 30 | G5: 42 | H5: 5 | I5: 10 | J5: 1 | K5: 851.79367 | L5: =(K5-N5)/(M5-N5) -> 0.72780832 | M5: 1047.752 | N5: 327.82432
A6: 1 | B6: 36 | C6: Uniform | D6: 300 | E6: 3 | F6: 30 | G6: 42 | H6: 5 | I6: 10 | J6: 2 | K6: 686.90693 | L6: =(K6-N6)/(M6-N6) -> 0.49877595 | M6: 1047.752 | N6: 327.82432
A7: 1 | B7: 36 | C7: Uniform | D7: 300 | E7: 3 | F7: 30 | G7: 42 | H7: 5 | I7: 10 | J7: 3 | K7: 686.90693 | L7: =(K7-N7)/(M7-N7) -> 0.49877595 | M7: 1047.752 | N7: 327.82432
A8: 1 | B8: 36 | C8: Uniform | D8: 300 | E8: 3 | F8: 30 | G8: 42 | H8: 1 | I8: 5 | J8: 1 | K8: 686.90693 | L8: =(K8-N8)/(M8-N8) -> 0.49877595 | M8: 1047.752 | N8: 327.82432
A9: 1 | B9: 36 | C9: Uniform | D9: 300 | E9: 3 | F9: 30 | G9: 42 | H9: 1 | I9: 5 | J9: 2 | K9: 686.90693 | L9: =(K9-N9)/(M9-N9) -> 0.49877595 | M9: 1047.752 | N9: 327.82432
A10: 1 | B10: 36 | C10: Uniform | D10: 300 | E10: 3 | F10: 30 | G10: 42 | H10: 1 | I10: 5 | J10: 3 | K10: 682.05983 | L10: =(K10-N10)/(M10-N10) -> 0.49204319 | M10: 1047.752 | N10: 327.82432
A11: 1 | B11: 36 | C11: Uniform | D11: 300 | E11: 3 | F11: 30 | G11: 42 | H11: 1 | I11: 10 | J11: 1 | K11: 678.81556 | L11: =(K11-N11)/(M11-N11) -> 0.48753681 | M11: 1047.752 | N11: 327.82432
A12: 1 | B12: 36 | C12: Uniform | D12: 300 | E12: 3 | F12: 30 | G12: 42 | H12: 1 | I12: 10 | J12: 2 | K12: 327.82432 | L12: =(K12-N12)/(M12-N12) -> 5.864343e-11 | M12: 1047.752 | N12: 327.82432
A13: 1 | B13: 36 | C13: Uniform | D13: 300 | E13: 3 | F13: 30 | G13: 42 | H13: 1 | I13: 10 | J13: 3 | K13: 327.82432 | L13: =(K13-N13)/(M13-N13) -> 5.864343e-11 | M13: 1047.752 | N13: 327.82432
J14: 1
J15: 2
J16: 3
J17: 1
J18: 2
J19: 3
A20: 1 | B20: 36 | C20: Uniform | D20: 300 | E20: 3 | F20: 30 | G20: 42 | H20: 15 | I20: 5 | J20: 1 | K20: 686.90693 | L20: =(K20-N20)/(M20-N20) -> 0.49877595 | M20: 1047.752 | N20: 327.82432
A21: 1 | B21: 36 | C21: Uniform | D21: 300 | E21: 3 | F21: 30 | G21: 42 | H21: 15 | I21: 5 | J21: 2 | K21: 686.90693 | L21: =(K21-N21)/(M21-N21) -> 0.49877595 | M21: 1047.752 | N21: 327.82432
A22: 1 | B22: 36 | C22: Uniform | D22: 300 | E22: 3 | F22: 30 | G22: 42 | H22: 15 | I22: 5 | J22: 3 | K22: 686.90693 | L22: =(K22-N22)/(M22-N22) -> 0.49877595 | M22: 1047.752 | N22: 327.82432
A23: 1 | B23: 36 | C23: Uniform | D23: 300 | E23: 3 | F23: 30 | G23: 42 | H23: 15 | I23: 10 | J23: 1 | K23: 686.90693 | L23: =(K23-N23)/(M23-N23) -> 0.49877595 | M23: 1047.752 | N23: 327.82432
A24: 1 | B24: 36 | C24: Uniform | D24: 300 | E24: 3 | F24: 30 | G24: 42 | H24: 15 | I24: 10 | J24: 2 | K24: 686.90693 | L24: =(K24-N24)/(M24-N24) -> 0.49877595 | M24: 1047.752 | N24: 327.82432
A25: 1 | B25: 36 | C25: Uniform | D25: 300 | E25: 3 | F25: 30 | G25: 42 | H25: 15 | I25: 10 | J25: 3 | K25: 686.90693 | L25: =(K25-N25)/(M25-N25) -> 0.49877595 | M25: 1047.752 | N25: 327.82432
A26: 1 | B26: 36 | C26: Uniform | D26: 300 | E26: 3 | F26: 30 | G26: 42 | H26: 1 | I26: 7.5 | J26: 1 | K26: 686.90693 | L26: =(K26-N26)/(M26-N26) -> 0.49877595 | M26: 1047.752 | N26: 327.82432
A27: 1 | B27: 36 | C27: Uniform | D27: 300 | E27: 3 | F27: 30 | G27: 42 | H27: 1 | I27: 7.5 | J27: 2 | K27: 686.90693 | L27: =(K27-N27)/(M27-N27) -> 0.49877595 | M27: 1047.752 | N27: 327.82432
A28: 1 | B28: 36 | C28: Uniform | D28: 300 | E28: 3 | F28: 30 | G28: 42 | H28: 1 | I28: 7.5 | J28: 3 | K28: 693.51648 | L28: =(K28-N28)/(M28-N28) -> 0.50795681 | M28: 1047.752 | N28: 327.82432
A29: 1 | B29: 36 | C29: Uniform | D29: 300 | E29: 3 | F29: 30 | G29: 42 | H29: 5 | I29: 7.5 | J29: 1 | K29: 686.90693 | L29: =(K29-N29)/(M29-N29) -> 0.49877595 | M29: 1047.752 | N29: 327.82432
A30: 1 | B30: 36 | C30: Uniform | D30: 300 | E30: 3 | F30: 30 | G30: 42 | H30: 5 | I30: 7.5 | J30: 2 | K30: 686.90693 | L30: =(K30-N30)/(M30-N30) -> 0.49877595 | M30: 1047.752 | N30: 327.82432
A31: 1 | B31: 36 | C31: Uniform | D31: 300 | E31: 3 | F31: 30 | G31: 42 | H31: 5 | I31: 7.5 | J31: 3 | K31: 686.90693 | L31: =(K31-N31)/(M31-N31) -> 0.49877595 | M31: 1047.752 | N31: 327.82432
... A43: 1 | B43: 36 | C43: Uniform | D43: 42 | E43: 15 | F43: 20 | G43: 42 | H43: 15 | I43: 50 | J43: 3 | K43: 686.90693 | L43: =(K43-N43)/(M43-N43) -> 0.49877595 | M43: 1047.752 | N43: 327.82432
D44: 300 | E44: 3 | F44: 30 | J44: 1
D45: 300 | E45: 3 | F45: 30 | J45: 2
D46: 300 | E46: 3 | F46: 30 | J46: 3
